<?xml version="1.0" encoding="UTF-8"?>
<testng-results skipped="0" failed="2" total="2" passed="0">
  <reporter-output>
  </reporter-output>
  <suite name="example.NewTest" duration-ms="35133" started-at="2016-04-07T06:12:37Z" finished-at="2016-04-07T06:13:12Z">
    <groups>
    </groups>
    <test name="Command line test" duration-ms="35133" started-at="2016-04-07T06:12:37Z" finished-at="2016-04-07T06:13:12Z">
      <class name="example.NewTest">
        <test-method status="PASS" signature="beforeTest()[pri:0, instance:example.NewTest@4049cab1]" name="beforeTest" is-config="true" duration-ms="14320" started-at="2016-04-07T01:12:37Z" finished-at="2016-04-07T01:12:52Z">
          <reporter-output>
          </reporter-output>
        </test-method> <!-- beforeTest -->
        <test-method status="FAIL" signature="firstTest()[pri:0, instance:example.NewTest@4049cab1]" name="firstTest" duration-ms="12839" started-at="2016-04-07T01:12:52Z" finished-at="2016-04-07T01:13:04Z">
          <exception class="java.lang.AssertionError">
            <message>
              <![CDATA[expected [true] but found [false]]]>
            </message>
            <full-stacktrace>
              <![CDATA[java.lang.AssertionError: expected [true] but found [false]
	at org.testng.Assert.fail(Assert.java:94)
	at org.testng.Assert.failNotEquals(Assert.java:513)
	at org.testng.Assert.assertTrue(Assert.java:42)
	at org.testng.Assert.assertTrue(Assert.java:52)
	at example.NewTest.firstTest(NewTest.java:20)
	at sun.reflect.NativeMethodAccessorImpl.invoke0(Native Method)
	at sun.reflect.NativeMethodAccessorImpl.invoke(Unknown Source)
	at sun.reflect.DelegatingMethodAccessorImpl.invoke(Unknown Source)
	at java.lang.reflect.Method.invoke(Unknown Source)
	at org.testng.internal.MethodInvocationHelper.invokeMethod(MethodInvocationHelper.java:86)
	at org.testng.internal.Invoker.invokeMethod(Invoker.java:643)
	at org.testng.internal.Invoker.invokeTestMethod(Invoker.java:820)
	at org.testng.internal.Invoker.invokeTestMethods(Invoker.java:1128)
	at org.testng.internal.TestMethodWorker.invokeTestMethods(TestMethodWorker.java:129)
	at org.testng.internal.TestMethodWorker.run(TestMethodWorker.java:112)
	at org.testng.TestRunner.privateRun(TestRunner.java:782)
	at org.testng.TestRunner.run(TestRunner.java:632)
	at org.testng.SuiteRunner.runTest(SuiteRunner.java:366)
	at org.testng.SuiteRunner.runSequentially(SuiteRunner.java:361)
	at org.testng.SuiteRunner.privateRun(SuiteRunner.java:319)
	at org.testng.SuiteRunner.run(SuiteRunner.java:268)
	at org.testng.SuiteRunnerWorker.runSuite(SuiteRunnerWorker.java:52)
	at org.testng.SuiteRunnerWorker.run(SuiteRunnerWorker.java:86)
	at org.testng.TestNG.runSuitesSequentially(TestNG.java:1244)
	at org.testng.TestNG.runSuitesLocally(TestNG.java:1169)
	at org.testng.TestNG.run(TestNG.java:1064)
	at org.apache.maven.surefire.testng.TestNGExecutor.run(TestNGExecutor.java:77)
	at org.apache.maven.surefire.testng.TestNGDirectoryTestSuite.execute(TestNGDirectoryTestSuite.java:110)
	at org.apache.maven.surefire.testng.TestNGProvider.invoke(TestNGProvider.java:106)
	at sun.reflect.NativeMethodAccessorImpl.invoke0(Native Method)
	at sun.reflect.NativeMethodAccessorImpl.invoke(Unknown Source)
	at sun.reflect.DelegatingMethodAccessorImpl.invoke(Unknown Source)
	at java.lang.reflect.Method.invoke(Unknown Source)
	at org.apache.maven.surefire.util.ReflectionUtils.invokeMethodWithArray(ReflectionUtils.java:189)
	at org.apache.maven.surefire.booter.ProviderFactory$ProviderProxy.invoke(ProviderFactory.java:165)
	at org.apache.maven.surefire.booter.ProviderFactory.invokeProvider(ProviderFactory.java:85)
	at org.apache.maven.surefire.booter.ForkedBooter.runSuitesInProcess(ForkedBooter.java:115)
	at org.apache.maven.surefire.booter.ForkedBooter.main(ForkedBooter.java:75)
]]>
            </full-stacktrace>
          </exception> <!-- java.lang.AssertionError -->
          <reporter-output>
          </reporter-output>
        </test-method> <!-- firstTest -->
        <test-method status="FAIL" signature="secondTest()[pri:0, instance:example.NewTest@4049cab1]" name="secondTest" duration-ms="6964" started-at="2016-04-07T01:13:04Z" finished-at="2016-04-07T01:13:11Z">
          <exception class="java.lang.AssertionError">
            <message>
              <![CDATA[expected [true] but found [false]]]>
            </message>
            <full-stacktrace>
              <![CDATA[java.lang.AssertionError: expected [true] but found [false]
	at org.testng.Assert.fail(Assert.java:94)
	at org.testng.Assert.failNotEquals(Assert.java:513)
	at org.testng.Assert.assertTrue(Assert.java:42)
	at org.testng.Assert.assertTrue(Assert.java:52)
	at example.NewTest.secondTest(NewTest.java:28)
	at sun.reflect.NativeMethodAccessorImpl.invoke0(Native Method)
	at sun.reflect.NativeMethodAccessorImpl.invoke(Unknown Source)
	at sun.reflect.DelegatingMethodAccessorImpl.invoke(Unknown Source)
	at java.lang.reflect.Method.invoke(Unknown Source)
	at org.testng.internal.MethodInvocationHelper.invokeMethod(MethodInvocationHelper.java:86)
	at org.testng.internal.Invoker.invokeMethod(Invoker.java:643)
	at org.testng.internal.Invoker.invokeTestMethod(Invoker.java:820)
	at org.testng.internal.Invoker.invokeTestMethods(Invoker.java:1128)
	at org.testng.internal.TestMethodWorker.invokeTestMethods(TestMethodWorker.java:129)
	at org.testng.internal.TestMethodWorker.run(TestMethodWorker.java:112)
	at org.testng.TestRunner.privateRun(TestRunner.java:782)
	at org.testng.TestRunner.run(TestRunner.java:632)
	at org.testng.SuiteRunner.runTest(SuiteRunner.java:366)
	at org.testng.SuiteRunner.runSequentially(SuiteRunner.java:361)
	at org.testng.SuiteRunner.privateRun(SuiteRunner.java:319)
	at org.testng.SuiteRunner.run(SuiteRunner.java:268)
	at org.testng.SuiteRunnerWorker.runSuite(SuiteRunnerWorker.java:52)
	at org.testng.SuiteRunnerWorker.run(SuiteRunnerWorker.java:86)
	at org.testng.TestNG.runSuitesSequentially(TestNG.java:1244)
	at org.testng.TestNG.runSuitesLocally(TestNG.java:1169)
	at org.testng.TestNG.run(TestNG.java:1064)
	at org.apache.maven.surefire.testng.TestNGExecutor.run(TestNGExecutor.java:77)
	at org.apache.maven.surefire.testng.TestNGDirectoryTestSuite.execute(TestNGDirectoryTestSuite.java:110)
	at org.apache.maven.surefire.testng.TestNGProvider.invoke(TestNGProvider.java:106)
	at sun.reflect.NativeMethodAccessorImpl.invoke0(Native Method)
	at sun.reflect.NativeMethodAccessorImpl.invoke(Unknown Source)
	at sun.reflect.DelegatingMethodAccessorImpl.invoke(Unknown Source)
	at java.lang.reflect.Method.invoke(Unknown Source)
	at org.apache.maven.surefire.util.ReflectionUtils.invokeMethodWithArray(ReflectionUtils.java:189)
	at org.apache.maven.surefire.booter.ProviderFactory$ProviderProxy.invoke(ProviderFactory.java:165)
	at org.apache.maven.surefire.booter.ProviderFactory.invokeProvider(ProviderFactory.java:85)
	at org.apache.maven.surefire.booter.ForkedBooter.runSuitesInProcess(ForkedBooter.java:115)
	at org.apache.maven.surefire.booter.ForkedBooter.main(ForkedBooter.java:75)
]]>
            </full-stacktrace>
          </exception> <!-- java.lang.AssertionError -->
          <reporter-output>
          </reporter-output>
        </test-method> <!-- secondTest -->
        <test-method status="PASS" signature="afterTest()[pri:0, instance:example.NewTest@4049cab1]" name="afterTest" is-config="true" duration-ms="987" started-at="2016-04-07T01:13:11Z" finished-at="2016-04-07T01:13:12Z">
          <reporter-output>
          </reporter-output>
        </test-method> <!-- afterTest -->
      </class> <!-- example.NewTest -->
    </test> <!-- Command line test -->
  </suite> <!-- example.NewTest -->
</testng-results>
